Workbook

Sheet Revision List
A1: REVISION
A2: SUBMITTED BY: | B2: REV. LEVEL: | C2: REV. DATE: | D2: DESCRIPTION | E2: APPROVAL DATE: | F2: APPROVED BY:
A3: Tanner Dean | B3: 2 | C3: 45770 | D3: Added Drain Pan opening verification | E3: 45770 | F3: KAS
A4: Tanner Dean | B4: 3 | C4: 45777 | D4: Added Post Fab Release Verification Section | E4: 45777 | F4: DD
A5: Tanner Dean | B5: 4 | C5: 45793 | D5: Corrected wording on max wall size | E5: 45793 | F5: BB
A6: Tanner Dean | B6: 5 | C6: 45855 | D6: Updated some verification wording, added error calculator, added drain pan verification | E6: 45855 | F6: BB
A7: Tanner Dean | B7: 6 | C7: 45862 | D7: Added Purchased Material Report verifications; small verbiage changes on multiple lines | E7: 45862 | F7: BB
A8: Tanner Dean | B8: 7 | C8: 45876 | D8: Move Base9 to paperwork, Changed Base9 and added Base10; Updated internal verifications; added how to use. | E8: 45876 | F8: BB
A9: Tanner Dean | B9: 8 | C9: 45902 | D9: Added Part number verification to paperwork | E9: 45902 | F9: BB
A10: Tanner Dean | B10: 9 | C10: 46072 | D10: Combined CAD and ISG verification; added expandable groups; broke out key internals to their own group; added improved error tracker; reevaluated current verification list | E10: 46072 | F10: BB
A11: Tanner Dean | B11: 10 | C11: 46094 | D11: Minor grammatical and formatting fixes | E11: 46094 | F11: BB
A12: Tanner Dean | B12: 11 | C12: 46107 | D12: Added MOM section; minor changes to wording across various verification | E12: 46107 | F12: BB
A13: Tanner Dean | B13: 12 | C13: 46135 | D13: Added fan hats to base support verification; added type of error column; added special construction and ISG generation error trackers | E13: =C13 -> 46135 | F13: BB
A14: Tanner Dean | B14: 13 | C14: 46140 | D14: Added Detailer Name list | E14: =C14 -> 46140 | F14: BB

Sheet Verification List
AA1: Base
B2: UNIT DETAILING VERIFICATION LIST | U2: 46171 | Y2: Paperwork Verifications | AA2: Housing
B3: DETAILER: | G3: SQs & Deviation Items Related to Detailing | Y3: Change wall/roof specific to Housing | AA3: Fans
B4: DATE: | G4: 1 | Y4: MOM Verifications | Z4: Consolidate | AA4: Internals
B5: JOB NAME: | G5: 2 | AA5: Filters
B6: COM#: | G6: 3 | AA6: UTL
B7: SHELL TYPE: | G7: 4 | AA7: Drainpan
B8: UNIT TYPE: | G8: 5 | Z8: Paperwork
B9: BASE HEIGHT: | G9: 6 | Z9: MOM
B10: WALL THICKNESS: | G10: 7
B11: THERMAL BREAK: | G11: 8 | Y11: remove subgroups
B12: ROOF PEAK: | G12: 9
B13: CURBREST: | G13: 10
B14: NOA: | G14: 11
B15: SEISMIC: | G15: 12
B16: LOCATION: | G16: 13
B17: KNOCKDOWN: | G17: 14
B18: UTL: | G18: 15
B19: LINER MATERIAL | E19: GA | G19: 16
B20: SKIN MATERIAL | E20: GA | G20: 17
B21: FLOOR MATERIAL | E21: GA | G21: 18
B22: Additional Comments: | G22: 19
G23: 20
G24: 21
G25: 22 | Y25: Comments | Z25: Initials
B26: CAD Verifications
B27: Base
B28: Base Features | S28: N/A | T28: Detailer Check off | V28: Checker Check off
B29: 1 | C29: Lifting lugs Have proper support when the skid is over 4,000lbs (Ref ASSY Manual page 391-40206-003) | S29: FALSE | T29: FALSE | V29: FALSE | Y29: base 01
B30: 2 | C30: Lifting lugs are free of obstruction/interference around drains, coil connections, VFDs, etc. (Standard 6" minimum). | S30: FALSE | T30: FALSE | V30: FALSE | Y30: base 02 | Z30: k
B31: 3 | C31: Floor drains are present and located as shown on the Unit Editor. | S31: FALSE | T31: FALSE | V31: FALSE | Y31: base 03 | Z31: k
B32: 4 | C32: Floor drain hole sizes are correct. 3.125" dia for AL Drains; 1.50" dia for Steel Drains | S32: FALSE | T32: FALSE | V32: FALSE | Y32: base 04 | Z32: k
B33: 5 | C33: Drain Pan Drains are located on the correct hand per the UE | S33: FALSE | T33: FALSE | V33: FALSE | Y33: base 05 -> drainpan verification
B34: 6 | C34: Filler plate material is correct on aluminum base units. | S34: FALSE | T34: FALSE | V34: FALSE | Y34: base 06 -> remove
B35: 7 | C35: Construction splits and units splits are located where necessary. | S35: FALSE | T35: FALSE | V35: FALSE | Y35: base 07 -> remove
B36: Perimeter Angle | S36: N/A | T36: Detailer Check off | V36: Checker Check off
B37: 1 | C37: The perimeter angle codes are correct after deviating from configurator generated parts. | S37: FALSE | T37: FALSE | V37: FALSE | Y37: base 08 -> remove
B38: 2 | C38: Perimeter Angles are the correct material and have the correct attachment hole size. 0.25" dia for rivet connection; 0.50" for weld connection | S38: FALSE | T38: FALSE | V38: FALSE | Y38: base 09 -> remove
B39: Skins | S39: N/A | T39: Detailer Check off | V39: Checker Check off
B40: 1 | C40: Skin Seams have proper base steel support. | S40: FALSE | T40: FALSE | V40: FALSE | Y40: base 10
...

Sheet Check Information
A1: Check Information
A2: Detailer | B2: =IF(ISBLANK('Verification List'!D3)," ",'Verification List'!D3)
A3: COM | B3: =IF(ISBLANK('Verification List'!D6)," ",'Verification List'!D6)
A4: Checker
A5: Date Checked
A6: Error Tracker
A7: Type | B7: DR | C7: DVL
A8: Base Errors | B8: =Base!F1 -> 0 | C8: =Base!D1 -> 0
A9: Drain Pan Errors | B9: ='Drain Pan'!F1 -> 0 | C9: ='Drain Pan'!D1 -> 0
A10: Housing Errors | B10: =Housing!F1 -> 0 | C10: =Housing!D1 -> 0
A11: Paperwork Errors | B11: =Paperwork!F1 -> 0 | C11: =Paperwork!D1 -> 0
A12: Internal Component Errors | B12: =Internal!F1 -> 0 | C12: =Internal!D1 -> 0
A13: Coil Panel Errors | B13: ='Coil Panels'!F1 -> 0 | C13: ='Coil Panels'!D1 -> 0
A14: Reconnect Errors | B14: =Reconnects!F1 -> 0 | C14: =Reconnects!D1 -> 0
A15: MOM Errors | B15: =MOM!F1 -> 0 | C15: =MOM!D1 -> 0
A16: Total Errors | B16: =SUM(B8:B15) -> 0 | C16: =SUM(C8:C15) -> 0
A18: Verification List Errors Found | B18: =COUNTA('Verification List'!X5:X131) -> 0
A19: Special Construction Errors | B19: =Base!H1+'Drain Pan'!H1+Housing!H1+Paperwork!H1+Internal!H1+'Coil Panels'!H1+Reconnects!H1+MOM!H1 -> 0
A20: ISG Generation Errors | B20: =Base!J1+Housing!J1+Paperwork!J1 -> 0
A21: PE Errors
A22: Engineering Errors

Sheet Comments
A1: Detailer Comments | B1: Comments
B2: This tab is for leaving suggestions based off of review, not necessarily for correction but for future reference.

Sheet Base
A1: Detailer Comments/Completion | B1: Type of Error | C1: DVL Errors | D1: 0 | E1: DR Errors | F1: 0 | G1: Special Construction Errors | H1: 0 | I1: ISG Generation Issues | J1: 0
C3: Checks

Sheet Drain Pan
A1: Detailer Comments/Completion | B1: Type of Error | C1: DVL Errors | D1: 0 | E1: DR Errors | F1: 0 | G1: Special Construction Errors | H1: 0
C3: Checks

Sheet Housing
A1: Detailer Comments/Completion | B1: Type of Error | C1: DVL Errors | D1: 0 | E1: DR Errors | F1: 0 | G1: Special Construction Errors | H1: 0 | I1: ISG Generation Issues | J1: 0
C3: Checks

Sheet Paperwork
A1: Detailer Comments/Completion | B1: Type of Error | C1: DVL Errors | D1: 0 | E1: DR Errors | F1: 0 | G1: Special Construction Errors | H1: 0 | I1: ISG Generation Issues | J1: 0
C3: Checks

Sheet Internal
A1: Detailer Comments/Completion | B1: Type of Error | C1: DVL Errors | D1: 0 | E1: DR Errors | F1: 0 | G1: Special Construction Errors | H1: 0
C3: Checks

Sheet Coil Panels
A1: Detailer Comments/Completion | B1: Type of Error | C1: DVL Errors | D1: 0 | E1: DR Errors | F1: 0 | G1: Special Construction Errors | H1: 0
C3: Checks

Sheet Reconnects
A1: Detailer Comments/Completion | B1: Type of Error | C1: DVL Errors | D1: 0 | E1: DR Errors | F1: 0 | G1: Special Construction Errors | H1: 0
C3: Checks

Sheet MOM
A1: Detailer Comments/Completion | B1: Type of Error | C1: DVL Errors | D1: 0 | E1: DR Errors | F1: 0 | G1: Special Construction Errors | H1: 0
C3: Checks
